Workbook

Sheet サイズ ・付属
B1: Instruction Sheets
A2: Sample | I2: 1.サイズ・付属 | S2: DATE | T2: 2025 | W2: year | X2: 11 | Z2: month | AA2: 20 | AC2: day | AF2: Sim inc
W3: 年 | Z3: 月 | AC3: 日 | AD3: sim@simtokyo.com
A5: Contract No. | D5: Description | I5: Sample No. | L5: Style No. | P5: Store | R5: Shipper | U5: Factory | X5: Brand | Z5: Person in charge | AB5: Confirmed by | AD5: Planning Company | AH5: Printed by
A6: 契約番号 | D6: 商品名 | I6: 見本品番 | L6: 確定品番 | P6: 販売先 | R6: 契約先 | U6: 工場名 | X6: 商標 | Z6: 担当者 | AB6: 確認 | AD6: 企画会社 | AH6: 作成者
A7: --- | D7: Mens Easy Twill Pants | I7: 26sCR-P101 | L7: --- | R7: -- | U7: --- | AB7: --- | AD7: Sim inc | AH7: imamura
A9: 素材 | H9: 組成 | N9: 生地方向 ：差し込み 可能 | W9: 洗い加工 | AB9: 備考
N10: 裁断： 着内同方向組み合わせ 横裁断 /毛並無し | W10: 有り
N11: 柄合わせ ： 無し | U11: パターンNo | W11: 26sCR-P101-1st | Z11: 枚数 | AA11: 8P
A12: 絵 型 | S12: 位置/サイズ | W12: L(64) | AB12: 許容 | AC12: 各 寸 法
W13: 1st | AB13: 範囲 | AD13: M | AE13: L | AF13: LL
S14: 1 | T14: ウエスト上端 | W14: 80 | AD14: 75 | AE14: 80 | AF14: 85
S15: 2 | T15: ウエスト付け寸法 | W15: 112 | AD15: 106 | AE15: 112 | AF15: 118
S16: 3 | T16: ヒップ わたり上10cm位置 | W16: 118 | AD16: 112 | AE16: 118 | AF16: 124
S17: 4 | T17: 前股上/ﾍﾞﾙﾄ込み | W17: 32 | AD17: 31 | AE17: 32 | AF17: 33
S18: 5 | T18: 後股上/ﾍﾞﾙﾄ込み | W18: 39 | AD18: 38 | AE18: 39 | AF18: 40
S19: 6 | T19: 渡り巾 | W19: 36.5 | AD19: 35 | AE19: 36.5 | AF19: 38
S20: 7 | T20: 膝 巾/内股30C下 | W20: 26.5 | AD20: 25.5 | AE20: 26.5 | AF20: 27.5
S21: 8 | T21: 裾 巾 | W21: 20.5 | AD21: 19.8 | AE21: 20.5 | AF21: 21.2
S22: 9 | T22: 股 下/直下 | W22: 70 | AD22: 70 | AE22: 70 | AF22: 70
S23: 10 | T23: ウエストステッチ巾 | W23: 3.8 | AD23: 3.8 | AE23: 3.8 | AF23: 3.8
S24: 11
S25: 12 | T25: 腰ポケット口(カンヌキ間) | W25: 15.5 | AD25: 15 | AE25: 15.5 | AF25: 16
S26: 13 | T26: 後ポケット口 | W26: 16 | AD26: 15.5 | AE26: 16 | AF26: 16.5
S27: 14 | T27: 後ポケット丈 | W27: 18 | AD27: 17.5 | AE27: 18 | AF27: 18.5
S28: 15
S29: 16 | T29: ウエスト紐 | W29: 145 | AD29: 140 | AE29: 145 | AF29: 150
S30: 17
S31: 18
S32: 19
S33: 20
S34: 21
S35: 22
S36: 23
S37: 24
S38: 25
S39: 26
S40: 27
S41: 28
A42: 注意事項 | S42: 29
...

Sheet 縫製指示
B1: Instruction Sheets
A2: ='サイズ ・付属'!A2:G3 -> Sample | I2: 2. 縫 製 仕 様 | S2: DATE | T2: 2025 | W2: year | X2: 11 | Z2: month | AA2: 20 | AC2: day | AF2: Sim inc
AD3: sim@simtokyo.com
A5: Contract No. | D5: Description | I5: Sample No. | L5: Style No. | P5: Store | R5: Shipper | U5: Factory | X5: Brand | Z5: Person in charge | AB5: Confirmed by | AD5: Planning Company | AH5: Printed by
A6: 契約番号 | D6: 商品名 | I6: 見本品番 | L6: 確定品番 | P6: 販売先 | R6: 契約先 | U6: 工場名 | X6: 商標 | Z6: 担当者 | AB6: 確認 | AD6: 企画会社 | AH6: 作成者
A7: ='サイズ ・付属'!A7:C7 -> --- | D7: Mens Easy Twill Pants | I7: 26sCR-P101 | L7: ='サイズ ・付属'!L7:O7 -> --- | P7: ='サイズ ・付属'!P7:Q7 -> 0 | R7: ='サイズ ・付属'!R7:T7 -> -- | U7: ='サイズ ・付属'!U7:W7 -> --- | AB7: ='サイズ ・付属'!AB7:AC7 -> --- | AD7: ='サイズ ・付属'!AD7:AG7 -> Sim inc | AH7: ='サイズ ・付属'!AH7:AI7 -> imamura | AL7: 部分は入力不可

Sheet パーツリスト
B1: Instruction Sheets
A2: ='サイズ ・付属'!A2:G3 -> Sample | I2: 3. パーツリスト | S2: DATE | T2: 2025 | W2: year | X2: 11 | Z2: month | AA2: 20 | AC2: day | AF2: Sim inc
AD3: sim@simtokyo.com
A5: Contract No. | D5: Description | I5: Sample No. | L5: Style No. | P5: Store | R5: Shipper | U5: Factory | X5: Brand | Z5: Person in charge | AB5: Confirmed by | AD5: Planning Company | AH5: Printed by
A6: 契約番号 | D6: 商品名 | I6: 見本品番 | L6: 確定品番 | P6: 販売先 | R6: 契約先 | U6: 工場名 | X6: 商標 | Z6: 担当者 | AB6: 確認 | AD6: 企画会社 | AH6: 作成者
A7: ='サイズ ・付属'!A7:C7 -> --- | D7: Mens Easy Twill Pants | I7: 26sCR-P101 | L7: ='サイズ ・付属'!L7:O7 -> --- | P7: ='サイズ ・付属'!P7:Q7 -> 0 | R7: ='サイズ ・付属'!R7:T7 -> -- | U7: ='サイズ ・付属'!U7:W7 -> --- | AB7: ='サイズ ・付属'!AB7:AC7 -> --- | AD7: ='サイズ ・付属'!AD7:AG7 -> Sim inc | AH7: ='サイズ ・付属'!AH7:AI7 -> imamura | AL7: 部分は入力不可

Sheet まとめ梱包
B1: Instruction Sheets
A2: Sample | I2: 4. 加 工 指 示 | S2: DATE | T2: 2025 | W2: year | X2: 10 | Z2: month | AA2: 31 | AC2: day | AF2: Sim inc
AD3: sim@simtokyo.com
A5: Contract No. | D5: Description | I5: Sample No. | L5: Style No. | P5: Store | R5: Shipper | U5: Factory | X5: Brand | Z5: Person in charge | AB5: Confirmed by | AD5: Planning Company | AH5: Printed by
A6: 契約番号 | D6: 商品名 | I6: 見本品番 | L6: 確定品番 | P6: 販売先 | R6: 契約先 | U6: 工場名 | X6: 商標 | Z6: 担当者 | AB6: 確認 | AD6: 企画会社 | AH6: 作成者
A7: ='サイズ ・付属'!A7:C7 -> --- | D7: Mens Easy Twill Pants | I7: 26sCR-P101 | L7: ='サイズ ・付属'!L7:O7 -> --- | P7: ='サイズ ・付属'!P7:Q7 -> 0 | R7: ='サイズ ・付属'!R7:T7 -> -- | U7: ='サイズ ・付属'!U7:W7 -> --- | AB7: ='サイズ ・付属'!AB7:AC7 -> --- | AD7: ='サイズ ・付属'!AD7:AG7 -> Sim inc | AH7: ='サイズ ・付属'!AH7:AI7 -> imamura | AL7: 部分は入力不可
A9: color/付属 | E9: 品質表示 | G9: ネーム | I9: サイズネーム | Q9: 下げ札-1 | S9: 下げ札−２ | Y9: ビニール袋
B10: 品番
A20: 使用箇所
A22: 手配先

Sheet 検品
B1: Instruction Sheets
A2: Sample | I2: 検 品 指 示 書 | S2: DATE | T2: 2025 | W2: year | X2: 10 | Z2: month | AA2: 31 | AC2: day | AF2: Sim inc
AD3: sim@simtokyo.com
A5: Contract No. | D5: Description | I5: Sample No. | L5: Style No. | P5: Store | R5: Shipper | U5: Factory | X5: Brand | Z5: Person in charge | AB5: Confirmed by | AD5: Planning Company | AH5: Printed by
A6: 契約番号 | D6: 商品名 | I6: 見本品番 | L6: 確定品番 | P6: 販売先 | R6: 契約先 | U6: 工場名 | X6: 商標 | Z6: 担当者 | AB6: 確認 | AD6: 企画会社 | AH6: 作成者
A7: ='サイズ ・付属'!A7:C7 -> --- | D7: Mens Easy Twill Pants | I7: 26sCR-P101 | L7: ='サイズ ・付属'!L7:O7 -> --- | P7: ='サイズ ・付属'!P7:Q7 -> 0 | R7: ='サイズ ・付属'!R7:T7 -> -- | U7: ='サイズ ・付属'!U7:W7 -> --- | Z7: 石田 | AB7: ='サイズ ・付属'!AB7:AC7 -> --- | AD7: ='サイズ ・付属'!AD7:AG7 -> Sim inc | AH7: ='サイズ ・付属'!AH7:AI7 -> imamura | AL7: 部分は入力不可
A9: 位置/サイズ | E9: L | F9: SPL作成日 | AC9: 検品箇所 | AG9: チェック
E10: 1st | F10: SPL | G10: 誤差 | H10: ●❌
A11: 1 | AC11: A | AD11: 表地
A12: 2 | AC12: B | AD12: 裏地
A13: 3 | AC13: C | AD13: 芯貼り
A14: 4 | AC14: D | AD14: 柄合わせ
A15: 5 | AC15: E | AD15: 衿付け
A16: 6 | AC16: F | AD16: 袖付け
A17: 7 | AC17: G | AD17: ポケット
A18: 8 | AC18: H | AD18: ウエストベルト
A19: 9 | AC19: I | AD19: ベルト通し
A20: 10 | AC20: J | AD20: ファスナー付け
A21: 11 | AC21: K
A22: 12 | AC22: L | AD22: 地縫い
A23: 13 | AC23: M | AD23: ステッチ
A24: 14 | AC24: N | AD24: ロック
A25: 15 | AC25: O | AD25: カンヌキ
A26: 16 | AC26: P | AD26: 裾始末
A27: 17 | AC27: Q | AD27: 中とじ
A28: 18 | AC28: R | AD28: 肩パット
A29: 19 | AC29: S
A30: 20 | AC30: T | AD30: 釦付け
A31: 21 | AC31: U | AD31: 釦ホール
A32: 22 | AC32: V | AD32: 糸始末
A33: 23 | AC33: W | AD33: プレス
A34: 24 | AC34: X
A35: 25 | AC35: Y
A36: 26 | AC36: Z
A37: 27 | AC37: A2 | AD37: ブランドネーム
A38: 28 | AC38: B2 | AD38: サイズネーム
A39: 29 | AC39: C2 | AD39: 洗濯ネーム
A40: 30 | AC40: D2 | AD40: デメリットネーム
A41: ＊＊絵型・下げ札＊＊ | AC41: E2
AC42: F2
...
